2019-10-29 04:52:28,476 ERROR: Exception on /excel/test2 [GET] [in /home/skullquake/src/skullquake/pythonsamples/src/venv/lib/python3.6/site-packages/flask/app.py:1891]
Traceback (most recent call last):
  File "/home/skullquake/src/skullquake/pythonsamples/src/venv/lib/python3.6/site-packages/flask/app.py", line 2446, in wsgi_app
    response = self.full_dispatch_request()
  File "/home/skullquake/src/skullquake/pythonsamples/src/venv/lib/python3.6/site-packages/flask/app.py", line 1951, in full_dispatch_request
    rv = self.handle_user_exception(e)
  File "/home/skullquake/src/skullquake/pythonsamples/src/venv/lib/python3.6/site-packages/flask/app.py", line 1820, in handle_user_exception
    reraise(exc_type, exc_value, tb)
  File "/home/skullquake/src/skullquake/pythonsamples/src/venv/lib/python3.6/site-packages/flask/_compat.py", line 39, in reraise
    raise value
  File "/home/skullquake/src/skullquake/pythonsamples/src/venv/lib/python3.6/site-packages/flask/app.py", line 1949, in full_dispatch_request
    rv = self.dispatch_request()
  File "/home/skullquake/src/skullquake/pythonsamples/src/venv/lib/python3.6/site-packages/flask/app.py", line 1935, in dispatch_request
    return self.view_functions[rule.endpoint](**req.view_args)
  File "/home/skullquake/src/skullquake/pythonsamples/src/flsk_mt_010/app/excel/routes.py", line 55, in test2
    return send_file(output,mimetype='application/vnd.openxmlformats-officedocument.spreadsheetml.sheet')
NameError: name 'send_file' is not defined
2019-10-29 04:52:51,871 INFO: Microblog startup [in /home/skullquake/src/skullquake/pythonsamples/src/flsk_mt_010/app/__init__.py:75]
2019-10-29 04:54:25,006 INFO: Microblog startup [in /home/skullquake/src/skullquake/pythonsamples/src/flsk_mt_010/app/__init__.py:75]
2019-10-29 04:54:29,007 ERROR: Exception on /excel/test2 [GET] [in /home/skullquake/src/skullquake/pythonsamples/src/venv/lib/python3.6/site-packages/flask/app.py:1891]
Traceback (most recent call last):
  File "/home/skullquake/src/skullquake/pythonsamples/src/venv/lib/python3.6/site-packages/flask/app.py", line 2446, in wsgi_app
    response = self.full_dispatch_request()
  File "/home/skullquake/src/skullquake/pythonsamples/src/venv/lib/python3.6/site-packages/flask/app.py", line 1951, in full_dispatch_request
    rv = self.handle_user_exception(e)
  File "/home/skullquake/src/skullquake/pythonsamples/src/venv/lib/python3.6/site-packages/flask/app.py", line 1820, in handle_user_exception
    reraise(exc_type, exc_value, tb)
  File "/home/skullquake/src/skullquake/pythonsamples/src/venv/lib/python3.6/site-packages/flask/_compat.py", line 39, in reraise
    raise value
  File "/home/skullquake/src/skullquake/pythonsamples/src/venv/lib/python3.6/site-packages/flask/app.py", line 1949, in full_dispatch_request
    rv = self.dispatch_request()
  File "/home/skullquake/src/skullquake/pythonsamples/src/venv/lib/python3.6/site-packages/flask/app.py", line 1935, in dispatch_request
    return self.view_functions[rule.endpoint](**req.view_args)
  File "/home/skullquake/src/skullquake/pythonsamples/src/flsk_mt_010/app/excel/routes.py", line 58, in test2
    return send_file(output,'asdf.xlsx',mimetype='application/vnd.openxmlformats-officedocument.spreadsheetml.sheet')
TypeError: send_file() got multiple values for argument 'mimetype'
2019-10-29 04:54:45,023 INFO: Microblog startup [in /home/skullquake/src/skullquake/pythonsamples/src/flsk_mt_010/app/__init__.py:75]
2019-10-29 04:54:46,107 ERROR: Exception on /excel/test2 [GET] [in /home/skullquake/src/skullquake/pythonsamples/src/venv/lib/python3.6/site-packages/flask/app.py:1891]
Traceback (most recent call last):
  File "/home/skullquake/src/skullquake/pythonsamples/src/venv/lib/python3.6/site-packages/flask/app.py", line 2446, in wsgi_app
    response = self.full_dispatch_request()
  File "/home/skullquake/src/skullquake/pythonsamples/src/venv/lib/python3.6/site-packages/flask/app.py", line 1951, in full_dispatch_request
    rv = self.handle_user_exception(e)
  File "/home/skullquake/src/skullquake/pythonsamples/src/venv/lib/python3.6/site-packages/flask/app.py", line 1820, in handle_user_exception
    reraise(exc_type, exc_value, tb)
  File "/home/skullquake/src/skullquake/pythonsamples/src/venv/lib/python3.6/site-packages/flask/_compat.py", line 39, in reraise
    raise value
  File "/home/skullquake/src/skullquake/pythonsamples/src/venv/lib/python3.6/site-packages/flask/app.py", line 1949, in full_dispatch_request
    rv = self.dispatch_request()
  File "/home/skullquake/src/skullquake/pythonsamples/src/venv/lib/python3.6/site-packages/flask/app.py", line 1935, in dispatch_request
    return self.view_functions[rule.endpoint](**req.view_args)
  File "/home/skullquake/src/skullquake/pythonsamples/src/flsk_mt_010/app/excel/routes.py", line 58, in test2
    return send_file(output,filename='asdf.xlsx',mimetype='application/vnd.openxmlformats-officedocument.spreadsheetml.sheet')
TypeError: send_file() got an unexpected keyword argument 'filename'
2019-10-29 04:54:57,239 INFO: Microblog startup [in /home/skullquake/src/skullquake/pythonsamples/src/flsk_mt_010/app/__init__.py:75]
2019-10-29 04:54:58,521 ERROR: Exception on /excel/test2 [GET] [in /home/skullquake/src/skullquake/pythonsamples/src/venv/lib/python3.6/site-packages/flask/app.py:1891]
Traceback (most recent call last):
  File "/home/skullquake/src/skullquake/pythonsamples/src/venv/lib/python3.6/site-packages/flask/app.py", line 2446, in wsgi_app
    response = self.full_dispatch_request()
  File "/home/skullquake/src/skullquake/pythonsamples/src/venv/lib/python3.6/site-packages/flask/app.py", line 1951, in full_dispatch_request
    rv = self.handle_user_exception(e)
  File "/home/skullquake/src/skullquake/pythonsamples/src/venv/lib/python3.6/site-packages/flask/app.py", line 1820, in handle_user_exception
    reraise(exc_type, exc_value, tb)
  File "/home/skullquake/src/skullquake/pythonsamples/src/venv/lib/python3.6/site-packages/flask/_compat.py", line 39, in reraise
    raise value
  File "/home/skullquake/src/skullquake/pythonsamples/src/venv/lib/python3.6/site-packages/flask/app.py", line 1949, in full_dispatch_request
    rv = self.dispatch_request()
  File "/home/skullquake/src/skullquake/pythonsamples/src/venv/lib/python3.6/site-packages/flask/app.py", line 1935, in dispatch_request
    return self.view_functions[rule.endpoint](**req.view_args)
  File "/home/skullquake/src/skullquake/pythonsamples/src/flsk_mt_010/app/excel/routes.py", line 58, in test2
    return send_file(output,name='asdf.xlsx',mimetype='application/vnd.openxmlformats-officedocument.spreadsheetml.sheet')
TypeError: send_file() got an unexpected keyword argument 'name'
2019-10-29 04:55:42,588 INFO: Microblog startup [in /home/skullquake/src/skullquake/pythonsamples/src/flsk_mt_010/app/__init__.py:75]
2019-10-29 04:56:27,370 INFO: Microblog startup [in /home/skullquake/src/skullquake/pythonsamples/src/flsk_mt_010/app/__init__.py:75]
2019-10-29 04:56:30,881 ERROR: Exception on /excel/test2 [GET] [in /home/skullquake/src/skullquake/pythonsamples/src/venv/lib/python3.6/site-packages/flask/app.py:1891]
Traceback (most recent call last):
  File "/home/skullquake/src/skullquake/pythonsamples/src/venv/lib/python3.6/site-packages/flask/app.py", line 2446, in wsgi_app
    response = self.full_dispatch_request()
  File "/home/skullquake/src/skullquake/pythonsamples/src/venv/lib/python3.6/site-packages/flask/app.py", line 1951, in full_dispatch_request
    rv = self.handle_user_exception(e)
  File "/home/skullquake/src/skullquake/pythonsamples/src/venv/lib/python3.6/site-packages/flask/app.py", line 1820, in handle_user_exception
    reraise(exc_type, exc_value, tb)
  File "/home/skullquake/src/skullquake/pythonsamples/src/venv/lib/python3.6/site-packages/flask/_compat.py", line 39, in reraise
    raise value
  File "/home/skullquake/src/skullquake/pythonsamples/src/venv/lib/python3.6/site-packages/flask/app.py", line 1949, in full_dispatch_request
    rv = self.dispatch_request()
  File "/home/skullquake/src/skullquake/pythonsamples/src/venv/lib/python3.6/site-packages/flask/app.py", line 1935, in dispatch_request
    return self.view_functions[rule.endpoint](**req.view_args)
  File "/home/skullquake/src/skullquake/pythonsamples/src/flsk_mt_010/app/excel/routes.py", line 58, in test2
    ret=send_file(output,mimetype='application/vnd.openxmlformats-officedocument.spreadsheetml.sheet',as_attachment=True,conditional=False)
  File "/home/skullquake/src/skullquake/pythonsamples/src/venv/lib/python3.6/site-packages/flask/helpers.py", line 601, in send_file
    raise TypeError("filename unavailable, required for sending as attachment")
TypeError: filename unavailable, required for sending as attachment
2019-10-29 04:57:25,537 INFO: Microblog startup [in /home/skullquake/src/skullquake/pythonsamples/src/flsk_mt_010/app/__init__.py:75]
2019-10-29 04:57:47,256 INFO: Microblog startup [in /home/skullquake/src/skullquake/pythonsamples/src/flsk_mt_010/app/__init__.py:75]
2019-10-29 05:00:15,323 INFO: Microblog startup [in /home/skullquake/src/skullquake/pythonsamples/src/flsk_mt_010/app/__init__.py:75]
2019-10-29 05:01:35,535 INFO: Microblog startup [in /home/skullquake/src/skullquake/pythonsamples/src/flsk_mt_010/app/__init__.py:75]
2019-10-29 05:07:46,552 INFO: Microblog startup [in /home/skullquake/src/skullquake/pythonsamples/src/flsk_mt_010/app/__init__.py:75]
