2019-10-24 15:53:22,098 ERROR: Exception on /psutil [GET] [in /data/data/com.termux/files/usr/lib/python3.7/site-packages/flask/app.py:1891]
Traceback (most recent call last):
  File "/data/data/com.termux/files/usr/lib/python3.7/site-packages/flask/app.py", line 2446, in wsgi_app
    response = self.full_dispatch_request()
  File "/data/data/com.termux/files/usr/lib/python3.7/site-packages/flask/app.py", line 1951, in full_dispatch_request
    rv = self.handle_user_exception(e)
  File "/data/data/com.termux/files/usr/lib/python3.7/site-packages/flask/app.py", line 1820, in handle_user_exception
    reraise(exc_type, exc_value, tb)
  File "/data/data/com.termux/files/usr/lib/python3.7/site-packages/flask/_compat.py", line 39, in reraise
    raise value
  File "/data/data/com.termux/files/usr/lib/python3.7/site-packages/flask/app.py", line 1949, in full_dispatch_request
    rv = self.dispatch_request()
  File "/data/data/com.termux/files/usr/lib/python3.7/site-packages/flask/app.py", line 1935, in dispatch_request
    return self.view_functions[rule.endpoint](**req.view_args)
  File "/data/data/com.termux/files/usr/lib/python3.7/site-packages/flask_login/utils.py", line 261, in decorated_view
    return func(*args, **kwargs)
  File "/data/data/com.termux/files/home/src/skullquake/pythonsamples/src/flsk_mt_009/app/routes.py", line 374, in _psutil
    'disk_io_counters':psutil.disk_io_counters(),
  File "/data/data/com.termux/files/usr/lib/python3.7/site-packages/psutil/__init__.py", line 2169, in disk_io_counters
    rawdict = _psplatform.disk_io_counters(**kwargs)
  File "/data/data/com.termux/files/usr/lib/python3.7/site-packages/psutil/_pslinux.py", line 1120, in disk_io_counters
    for entry in gen:
  File "/data/data/com.termux/files/usr/lib/python3.7/site-packages/psutil/_pslinux.py", line 1093, in read_procfs
    raise ValueError("not sure how to interpret line %r" % line)
ValueError: not sure how to interpret line '   1       0 ram0 0 0 0 0 0 0 0 0 0 0 0 0 0 0 0 0 0 61440 0 0 0 447051.003\n'
2019-10-24 15:53:22,935 ERROR: Exception on /psutil [GET] [in /data/data/com.termux/files/usr/lib/python3.7/site-packages/flask/app.py:1891]
Traceback (most recent call last):
  File "/data/data/com.termux/files/usr/lib/python3.7/site-packages/flask/app.py", line 2446, in wsgi_app
    response = self.full_dispatch_request()
  File "/data/data/com.termux/files/usr/lib/python3.7/site-packages/flask/app.py", line 1951, in full_dispatch_request
    rv = self.handle_user_exception(e)
  File "/data/data/com.termux/files/usr/lib/python3.7/site-packages/flask/app.py", line 1820, in handle_user_exception
    reraise(exc_type, exc_value, tb)
  File "/data/data/com.termux/files/usr/lib/python3.7/site-packages/flask/_compat.py", line 39, in reraise
    raise value
  File "/data/data/com.termux/files/usr/lib/python3.7/site-packages/flask/app.py", line 1949, in full_dispatch_request
    rv = self.dispatch_request()
  File "/data/data/com.termux/files/usr/lib/python3.7/site-packages/flask/app.py", line 1935, in dispatch_request
    return self.view_functions[rule.endpoint](**req.view_args)
  File "/data/data/com.termux/files/usr/lib/python3.7/site-packages/flask_login/utils.py", line 261, in decorated_view
    return func(*args, **kwargs)
  File "/data/data/com.termux/files/home/src/skullquake/pythonsamples/src/flsk_mt_009/app/routes.py", line 374, in _psutil
    'disk_io_counters':psutil.disk_io_counters(),
  File "/data/data/com.termux/files/usr/lib/python3.7/site-packages/psutil/__init__.py", line 2169, in disk_io_counters
    rawdict = _psplatform.disk_io_counters(**kwargs)
  File "/data/data/com.termux/files/usr/lib/python3.7/site-packages/psutil/_pslinux.py", line 1120, in disk_io_counters
    for entry in gen:
  File "/data/data/com.termux/files/usr/lib/python3.7/site-packages/psutil/_pslinux.py", line 1093, in read_procfs
    raise ValueError("not sure how to interpret line %r" % line)
ValueError: not sure how to interpret line '   1       0 ram0 0 0 0 0 0 0 0 0 0 0 0 0 0 0 0 0 0 61440 0 0 0 447051.840\n'
2019-10-24 15:53:23,615 ERROR: Exception on /psutil [GET] [in /data/data/com.termux/files/usr/lib/python3.7/site-packages/flask/app.py:1891]
Traceback (most recent call last):
  File "/data/data/com.termux/files/usr/lib/python3.7/site-packages/flask/app.py", line 2446, in wsgi_app
    response = self.full_dispatch_request()
  File "/data/data/com.termux/files/usr/lib/python3.7/site-packages/flask/app.py", line 1951, in full_dispatch_request
    rv = self.handle_user_exception(e)
  File "/data/data/com.termux/files/usr/lib/python3.7/site-packages/flask/app.py", line 1820, in handle_user_exception
    reraise(exc_type, exc_value, tb)
  File "/data/data/com.termux/files/usr/lib/python3.7/site-packages/flask/_compat.py", line 39, in reraise
    raise value
  File "/data/data/com.termux/files/usr/lib/python3.7/site-packages/flask/app.py", line 1949, in full_dispatch_request
    rv = self.dispatch_request()
  File "/data/data/com.termux/files/usr/lib/python3.7/site-packages/flask/app.py", line 1935, in dispatch_request
    return self.view_functions[rule.endpoint](**req.view_args)
  File "/data/data/com.termux/files/usr/lib/python3.7/site-packages/flask_login/utils.py", line 261, in decorated_view
    return func(*args, **kwargs)
  File "/data/data/com.termux/files/home/src/skullquake/pythonsamples/src/flsk_mt_009/app/routes.py", line 374, in _psutil
    'disk_io_counters':psutil.disk_io_counters(),
  File "/data/data/com.termux/files/usr/lib/python3.7/site-packages/psutil/__init__.py", line 2169, in disk_io_counters
    rawdict = _psplatform.disk_io_counters(**kwargs)
  File "/data/data/com.termux/files/usr/lib/python3.7/site-packages/psutil/_pslinux.py", line 1120, in disk_io_counters
    for entry in gen:
  File "/data/data/com.termux/files/usr/lib/python3.7/site-packages/psutil/_pslinux.py", line 1093, in read_procfs
    raise ValueError("not sure how to interpret line %r" % line)
ValueError: not sure how to interpret line '   1       0 ram0 0 0 0 0 0 0 0 0 0 0 0 0 0 0 0 0 0 61440 0 0 0 447052.520\n'
2019-10-24 15:53:24,441 ERROR: Exception on /psutil [GET] [in /data/data/com.termux/files/usr/lib/python3.7/site-packages/flask/app.py:1891]
Traceback (most recent call last):
  File "/data/data/com.termux/files/usr/lib/python3.7/site-packages/flask/app.py", line 2446, in wsgi_app
    response = self.full_dispatch_request()
  File "/data/data/com.termux/files/usr/lib/python3.7/site-packages/flask/app.py", line 1951, in full_dispatch_request
    rv = self.handle_user_exception(e)
  File "/data/data/com.termux/files/usr/lib/python3.7/site-packages/flask/app.py", line 1820, in handle_user_exception
    reraise(exc_type, exc_value, tb)
  File "/data/data/com.termux/files/usr/lib/python3.7/site-packages/flask/_compat.py", line 39, in reraise
    raise value
  File "/data/data/com.termux/files/usr/lib/python3.7/site-packages/flask/app.py", line 1949, in full_dispatch_request
    rv = self.dispatch_request()
  File "/data/data/com.termux/files/usr/lib/python3.7/site-packages/flask/app.py", line 1935, in dispatch_request
    return self.view_functions[rule.endpoint](**req.view_args)
  File "/data/data/com.termux/files/usr/lib/python3.7/site-packages/flask_login/utils.py", line 261, in decorated_view
    return func(*args, **kwargs)
  File "/data/data/com.termux/files/home/src/skullquake/pythonsamples/src/flsk_mt_009/app/routes.py", line 374, in _psutil
    'disk_io_counters':psutil.disk_io_counters(),
  File "/data/data/com.termux/files/usr/lib/python3.7/site-packages/psutil/__init__.py", line 2169, in disk_io_counters
    rawdict = _psplatform.disk_io_counters(**kwargs)
  File "/data/data/com.termux/files/usr/lib/python3.7/site-packages/psutil/_pslinux.py", line 1120, in disk_io_counters
    for entry in gen:
  File "/data/data/com.termux/files/usr/lib/python3.7/site-packages/psutil/_pslinux.py", line 1093, in read_procfs
    raise ValueError("not sure how to interpret line %r" % line)
ValueError: not sure how to interpret line '   1       0 ram0 0 0 0 0 0 0 0 0 0 0 0 0 0 0 0 0 0 61440 0 0 0 447053.347\n'
2019-10-24 15:53:25,078 ERROR: Exception on /psutil [GET] [in /data/data/com.termux/files/usr/lib/python3.7/site-packages/flask/app.py:1891]
Traceback (most recent call last):
  File "/data/data/com.termux/files/usr/lib/python3.7/site-packages/flask/app.py", line 2446, in wsgi_app
    response = self.full_dispatch_request()
  File "/data/data/com.termux/files/usr/lib/python3.7/site-packages/flask/app.py", line 1951, in full_dispatch_request
    rv = self.handle_user_exception(e)
  File "/data/data/com.termux/files/usr/lib/python3.7/site-packages/flask/app.py", line 1820, in handle_user_exception
    reraise(exc_type, exc_value, tb)
  File "/data/data/com.termux/files/usr/lib/python3.7/site-packages/flask/_compat.py", line 39, in reraise
    raise value
  File "/data/data/com.termux/files/usr/lib/python3.7/site-packages/flask/app.py", line 1949, in full_dispatch_request
    rv = self.dispatch_request()
  File "/data/data/com.termux/files/usr/lib/python3.7/site-packages/flask/app.py", line 1935, in dispatch_request
    return self.view_functions[rule.endpoint](**req.view_args)
  File "/data/data/com.termux/files/usr/lib/python3.7/site-packages/flask_login/utils.py", line 261, in decorated_view
    return func(*args, **kwargs)
  File "/data/data/com.termux/files/home/src/skullquake/pythonsamples/src/flsk_mt_009/app/routes.py", line 374, in _psutil
    'disk_io_counters':psutil.disk_io_counters(),
  File "/data/data/com.termux/files/usr/lib/python3.7/site-packages/psutil/__init__.py", line 2169, in disk_io_counters
    rawdict = _psplatform.disk_io_counters(**kwargs)
  File "/data/data/com.termux/files/usr/lib/python3.7/site-packages/psutil/_pslinux.py", line 1120, in disk_io_counters
    for entry in gen:
  File "/data/data/com.termux/files/usr/lib/python3.7/site-packages/psutil/_pslinux.py", line 1093, in read_procfs
    raise ValueError("not sure how to interpret line %r" % line)
ValueError: not sure how to interpret line '   1       0 ram0 0 0 0 0 0 0 0 0 0 0 0 0 0 0 0 0 0 61440 0 0 0 447053.984\n'
